<?xml version="1.0" encoding="utf-8" ?>
<!-- =================================================================================== -->
<!-- |    This document was autogenerated by xacro from /home/arpit/manas/ros_workspaces/robotic_arm_ws/src/robotic_arm_description/urdf/robotic_arm.xacro | -->
<!-- |    EDITING THIS FILE BY HAND IS NOT RECOMMENDED                                 | -->
<!-- =================================================================================== -->
<robot name="robotic_arm">
    <material name="silver">
        <color rgba="0.700 0.700 0.700 1.000" />
    </material>
    <transmission name="Rev11_tran">
        <type>transmission_interface/SimpleTransmission</type>
        <joint name="Rev11">
            <hardwareInterface>hardware_interface/EffortJointInterface</hardwareInterface>
        </joint>
        <actuator name="Rev11_actr">
            <hardwareInterface>hardware_interface/EffortJointInterface</hardwareInterface>
            <mechanicalReduction>1</mechanicalReduction>
        </actuator>
    </transmission>
    <transmission name="Rev12_tran">
        <type>transmission_interface/SimpleTransmission</type>
        <joint name="Rev12">
            <hardwareInterface>hardware_interface/EffortJointInterface</hardwareInterface>
        </joint>
        <actuator name="Rev12_actr">
            <hardwareInterface>hardware_interface/EffortJointInterface</hardwareInterface>
            <mechanicalReduction>1</mechanicalReduction>
        </actuator>
    </transmission>
    <transmission name="Rev13_tran">
        <type>transmission_interface/SimpleTransmission</type>
        <joint name="Rev13">
            <hardwareInterface>hardware_interface/EffortJointInterface</hardwareInterface>
        </joint>
        <actuator name="Rev13_actr">
            <hardwareInterface>hardware_interface/EffortJointInterface</hardwareInterface>
            <mechanicalReduction>1</mechanicalReduction>
        </actuator>
    </transmission>
    <transmission name="Rev14_tran">
        <type>transmission_interface/SimpleTransmission</type>
        <joint name="Rev14">
            <hardwareInterface>hardware_interface/EffortJointInterface</hardwareInterface>
        </joint>
        <actuator name="Rev14_actr">
            <hardwareInterface>hardware_interface/EffortJointInterface</hardwareInterface>
            <mechanicalReduction>1</mechanicalReduction>
        </actuator>
    </transmission>
    <transmission name="Rev15_tran">
        <type>transmission_interface/SimpleTransmission</type>
        <joint name="Rev15">
            <hardwareInterface>hardware_interface/EffortJointInterface</hardwareInterface>
        </joint>
        <actuator name="Rev15_actr">
            <hardwareInterface>hardware_interface/EffortJointInterface</hardwareInterface>
            <mechanicalReduction>1</mechanicalReduction>
        </actuator>
    </transmission>
    <transmission name="Rev16_tran">
        <type>transmission_interface/SimpleTransmission</type>
        <joint name="Rev16">
            <hardwareInterface>hardware_interface/EffortJointInterface</hardwareInterface>
        </joint>
        <actuator name="Rev16_actr">
            <hardwareInterface>hardware_interface/EffortJointInterface</hardwareInterface>
            <mechanicalReduction>1</mechanicalReduction>
        </actuator>
    </transmission>
    <transmission name="Rev17_tran">
        <type>transmission_interface/SimpleTransmission</type>
        <joint name="Rev17">
            <hardwareInterface>hardware_interface/EffortJointInterface</hardwareInterface>
        </joint>
        <actuator name="Rev17_actr">
            <hardwareInterface>hardware_interface/EffortJointInterface</hardwareInterface>
            <mechanicalReduction>1</mechanicalReduction>
        </actuator>
    </transmission>
    <transmission name="Rev18_tran">
        <type>transmission_interface/SimpleTransmission</type>
        <joint name="Rev18">
            <hardwareInterface>hardware_interface/EffortJointInterface</hardwareInterface>
        </joint>
        <actuator name="Rev18_actr">
            <hardwareInterface>hardware_interface/EffortJointInterface</hardwareInterface>
            <mechanicalReduction>1</mechanicalReduction>
        </actuator>
    </transmission>
    <transmission name="Rev19_tran">
        <type>transmission_interface/SimpleTransmission</type>
        <joint name="Rev19">
            <hardwareInterface>hardware_interface/EffortJointInterface</hardwareInterface>
        </joint>
        <actuator name="Rev19_actr">
            <hardwareInterface>hardware_interface/EffortJointInterface</hardwareInterface>
            <mechanicalReduction>1</mechanicalReduction>
        </actuator>
    </transmission>
    <gazebo>
        <plugin filename="libgazebo_ros_control.so" name="control" />
    </gazebo>
    <gazebo reference="base_link">
        <material>Gazebo/Silver</material>
        <mu1>0.2</mu1>
        <mu2>0.2</mu2>
        <selfCollide>true</selfCollide>
        <gravity>true</gravity>
    </gazebo>
    <gazebo reference="link1_1">
        <material>Gazebo/Silver</material>
        <mu1>0.2</mu1>
        <mu2>0.2</mu2>
        <selfCollide>true</selfCollide>
    </gazebo>
    <gazebo reference="link2_1">
        <material>Gazebo/Silver</material>
        <mu1>0.2</mu1>
        <mu2>0.2</mu2>
        <selfCollide>true</selfCollide>
    </gazebo>
    <gazebo reference="link3_1">
        <material>Gazebo/Silver</material>
        <mu1>0.2</mu1>
        <mu2>0.2</mu2>
        <selfCollide>true</selfCollide>
    </gazebo>
    <gazebo reference="link4_1">
        <material>Gazebo/Silver</material>
        <mu1>0.2</mu1>
        <mu2>0.2</mu2>
        <selfCollide>true</selfCollide>
    </gazebo>
    <gazebo reference="link5_1">
        <material>Gazebo/Silver</material>
        <mu1>0.2</mu1>
        <mu2>0.2</mu2>
        <selfCollide>true</selfCollide>
    </gazebo>
    <gazebo reference="link6_1">
        <material>Gazebo/Silver</material>
        <mu1>0.2</mu1>
        <mu2>0.2</mu2>
        <selfCollide>true</selfCollide>
    </gazebo>
    <gazebo reference="gripper_1">
        <material>Gazebo/Silver</material>
        <mu1>0.2</mu1>
        <mu2>0.2</mu2>
        <selfCollide>true</selfCollide>
    </gazebo>
    <gazebo reference="jaw2_1">
        <material>Gazebo/Silver</material>
        <mu1>0.2</mu1>
        <mu2>0.2</mu2>
        <selfCollide>true</selfCollide>
    </gazebo>
    <gazebo reference="jaw1_1">
        <material>Gazebo/Silver</material>
        <mu1>0.2</mu1>
        <mu2>0.2</mu2>
        <selfCollide>true</selfCollide>
    </gazebo>
    <link name="base_link">
        <visual>
            <origin rpy="0 0 0" xyz="0 0 0" />
            <geometry>
                <mesh filename="package://robotic_arm_description/meshes/base_link.stl" scale="0.001 0.001 0.001" />
            </geometry>
            <material name="silver" />
        </visual>
        <collision>
            <origin rpy="0 0 0" xyz="0 0 0" />
            <geometry>
                <mesh filename="package://robotic_arm_description/meshes/base_link.stl" scale="0.001 0.001 0.001" />
            </geometry>
        </collision>
        
<inertial>
            <mass value="0.1" />
            <inertia ixx="0.03" iyy="0.03" izz="0.03" ixy="0.0" ixz="0.0" iyz="0.0" />
        </inertial>

    </link>
    <link name="link1_1">
        
<inertial>
            <origin rpy="0 0 0" xyz="-0.014103177682961474 2.911659828472621e-08 0.09630243018941843" />
            <mass value="9.886638889856904" />
            <inertia ixx="0.028938" ixy="0.0" ixz="0.00225" iyy="0.029652" iyz="0.0" izz="0.010294" />
        </inertial>

        <visual>
            <origin rpy="0 0 0" xyz="-0.0 -0.0 -0.082" />
            <geometry>
                <mesh filename="package://robotic_arm_description/meshes/link1_1.stl" scale="0.001 0.001 0.001" />
            </geometry>
            <material name="silver" />
        </visual>
        <collision>
            <origin rpy="0 0 0" xyz="-0.0 -0.0 -0.082" />
            <geometry>
                <mesh filename="package://robotic_arm_description/meshes/link1_1.stl" scale="0.001 0.001 0.001" />
            </geometry>
        </collision>
    </link>
    <link name="link2_1">
        
<inertial>
            <origin rpy="0 0 0" xyz="0.03900552900187564 -4.720497574409756e-08 0.03774797355252993" />
            <mass value="8.491131635058604" />
            <inertia ixx="0.028031" ixy="0.0" ixz="0.002228" iyy="0.028711" iyz="0.0" izz="0.009465" />
        </inertial>

        <visual>
            <origin rpy="0 0 0" xyz="-0.025 -0.0 -0.214" />
            <geometry>
                <mesh filename="package://robotic_arm_description/meshes/link2_1.stl" scale="0.001 0.001 0.001" />
            </geometry>
            <material name="silver" />
        </visual>
        <collision>
            <origin rpy="0 0 0" xyz="-0.025 -0.0 -0.214" />
            <geometry>
                <mesh filename="package://robotic_arm_description/meshes/link2_1.stl" scale="0.001 0.001 0.001" />
            </geometry>
        </collision>
    </link>
    <link name="link3_1">
        
<inertial>
            <origin rpy="0 0 0" xyz="0.012475562747510771 1.9427211413704553e-08 0.09282105705277077" />
            <mass value="8.19717066814797" />
            <inertia ixx="0.027193" ixy="0.0" ixz="-0.001721" iyy="0.027471" iyz="0.0" izz="0.008682" />
        </inertial>

        <visual>
            <origin rpy="0 0 0" xyz="-0.05 -0.0 -0.346" />
            <geometry>
                <mesh filename="package://robotic_arm_description/meshes/link3_1.stl" scale="0.001 0.001 0.001" />
            </geometry>
            <material name="silver" />
        </visual>
        <collision>
            <origin rpy="0 0 0" xyz="-0.05 -0.0 -0.346" />
            <geometry>
                <mesh filename="package://robotic_arm_description/meshes/link3_1.stl" scale="0.001 0.001 0.001" />
            </geometry>
        </collision>
    </link>
    <link name="link4_1">
        
<inertial>
            <origin rpy="0 0 0" xyz="-0.0374755647664739 1.4871117923491877e-08 0.03917892822918834" />
            <mass value="8.197173492795319" />
            <inertia ixx="0.027193" ixy="-0.0" ixz="-0.001721" iyy="0.027471" iyz="-0.0" izz="0.008682" />
        </inertial>

        <visual>
            <origin rpy="0 0 0" xyz="-0.025 -0.0 -0.478" />
            <geometry>
                <mesh filename="package://robotic_arm_description/meshes/link4_1.stl" scale="0.001 0.001 0.001" />
            </geometry>
            <material name="silver" />
        </visual>
        <collision>
            <origin rpy="0 0 0" xyz="-0.025 -0.0 -0.478" />
            <geometry>
                <mesh filename="package://robotic_arm_description/meshes/link4_1.stl" scale="0.001 0.001 0.001" />
            </geometry>
        </collision>
    </link>
    <link name="link5_1">
        
<inertial>
            <origin rpy="0 0 0" xyz="5.829486113497266e-07 -0.013599717850522941 0.035950542831699184" />
            <mass value="2.7272453464013666" />
            <inertia ixx="0.005718" ixy="0.0" ixz="-0.0" iyy="0.005217" iyz="0.001527" izz="0.003392" />
        </inertial>

        <visual>
            <origin rpy="0 0 0" xyz="0.0 -0.0 -0.61" />
            <geometry>
                <mesh filename="package://robotic_arm_description/meshes/link5_1.stl" scale="0.001 0.001 0.001" />
            </geometry>
            <material name="silver" />
        </visual>
        <collision>
            <origin rpy="0 0 0" xyz="0.0 -0.0 -0.61" />
            <geometry>
                <mesh filename="package://robotic_arm_description/meshes/link5_1.stl" scale="0.001 0.001 0.001" />
            </geometry>
        </collision>
    </link>
    <link name="link6_1">
        
<inertial>
            <origin rpy="0 0 0" xyz="1.2404412177094015e-07 0.043907868057215506 0.00576385697550974" />
            <mass value="3.0329082890678123" />
            <inertia ixx="0.00335" ixy="0.0" ixz="-0.0" iyy="0.002555" iyz="-0.000289" izz="0.002524" />
        </inertial>

        <visual>
            <origin rpy="0 0 0" xyz="0.0 0.035 -0.737" />
            <geometry>
                <mesh filename="package://robotic_arm_description/meshes/link6_1.stl" scale="0.001 0.001 0.001" />
            </geometry>
            <material name="silver" />
        </visual>
        <collision>
            <origin rpy="0 0 0" xyz="0.0 0.035 -0.737" />
            <geometry>
                <mesh filename="package://robotic_arm_description/meshes/link6_1.stl" scale="0.001 0.001 0.001" />
            </geometry>
        </collision>
    </link>
    <link name="gripper_1">
        
<inertial>
            <origin rpy="0 0 0" xyz="6.519052686577514e-09 -0.00043894585194131225 0.008806436122391847" />
            <mass value="0.14002124283631304" />
            <inertia ixx="2.9e-05" ixy="0.0" ixz="0.0" iyy="4.7e-05" iyz="1e-06" izz="4.2e-05" />
        </inertial>

        <visual>
            <origin rpy="0 0 0" xyz="-0.0 -0.025 -0.797" />
            <geometry>
                <mesh filename="package://robotic_arm_description/meshes/gripper_1.stl" scale="0.001 0.001 0.001" />
            </geometry>
            <material name="silver" />
        </visual>
        <collision>
            <origin rpy="0 0 0" xyz="-0.0 -0.025 -0.797" />
            <geometry>
                <mesh filename="package://robotic_arm_description/meshes/gripper_1.stl" scale="0.001 0.001 0.001" />
            </geometry>
        </collision>
    </link>
    <link name="jaw2_1">
        
<inertial>
            <origin rpy="0 0 0" xyz="0.000131421896564822 0.0024996154528694157 0.015252945027369291" />
            <mass value="0.011516853958458544" />
            <inertia ixx="1e-06" ixy="0.0" ixz="-0.0" iyy="1e-06" iyz="-0.0" izz="0.0" />
        </inertial>

        <visual>
            <origin rpy="0 0 0" xyz="0.020495 -0.025 -0.843" />
            <geometry>
                <mesh filename="package://robotic_arm_description/meshes/jaw2_1.stl" scale="0.001 0.001 0.001" />
            </geometry>
            <material name="silver" />
        </visual>
        <collision>
            <origin rpy="0 0 0" xyz="0.020495 -0.025 -0.843" />
            <geometry>
                <mesh filename="package://robotic_arm_description/meshes/jaw2_1.stl" scale="0.001 0.001 0.001" />
            </geometry>
        </collision>
    </link>
    <link name="jaw1_1">
        
<inertial>
            <origin rpy="0 0 0" xyz="-0.0001314218965648116 0.0024996154528694157 0.015252945027369291" />
            <mass value="0.011516853958458544" />
            <inertia ixx="1e-06" ixy="0.0" ixz="0.0" iyy="1e-06" iyz="-0.0" izz="0.0" />
        </inertial>

        <visual>
            <origin rpy="0 0 0" xyz="-0.020495 -0.025 -0.843" />
            <geometry>
                <mesh filename="package://robotic_arm_description/meshes/jaw1_1.stl" scale="0.001 0.001 0.001" />
            </geometry>
            <material name="silver" />
        </visual>
        <collision>
            <origin rpy="0 0 0" xyz="-0.020495 -0.025 -0.843" />
            <geometry>
                <mesh filename="package://robotic_arm_description/meshes/jaw1_1.stl" scale="0.001 0.001 0.001" />
            </geometry>
        </collision>
    </link>
    <joint name="Rev11" type="continuous">
        <origin rpy="0 0 0" xyz="0.0 0.0 0.082" />
        <parent link="base_link" />
        <child link="link1_1" />
        <axis xyz="0.0 0.0 0.01" />
    </joint>
    <joint name="Rev12" type="revolute">
        <origin rpy="0 0 0" xyz="0.025 0.0 0.132" />
        <parent link="link1_1" />
        <child link="link2_1" />
        <axis xyz="0.01 0.0 0.0" />
        <limit effort="100" lower="-1.570796" upper="1.570796" velocity="100" />
    </joint>
    <joint name="Rev13" type="continuous">
        <origin rpy="0 0 0" xyz="0.025 0.0 0.132" />
        <parent link="link2_1" />
        <child link="link3_1" />
        <axis xyz="0.0 0.0 0.01" />
    </joint>
    <joint name="Rev14" type="revolute">
        <origin rpy="0 0 0" xyz="-0.025 0.0 0.132" />
        <parent link="link3_1" />
        <child link="link4_1" />
        <axis xyz="-0.01 0.0 0.0" />
        <limit effort="100" lower="-1.570796" upper="1.570796" velocity="100" />
    </joint>
    <joint name="Rev15" type="continuous">
        <origin rpy="0 0 0" xyz="-0.025 0.0 0.132" />
        <parent link="link4_1" />
        <child link="link5_1" />
        <axis xyz="0.0 -0.0 0.01" />
    </joint>
    <joint name="Rev16" type="revolute">
        <origin rpy="0 0 0" xyz="0.0 -0.035 0.127" />
        <parent link="link5_1" />
        <child link="link6_1" />
        <axis xyz="0.0 0.01 0.0" />
        <limit effort="100" lower="-1.570796" upper="1.570796" velocity="100" />
    </joint>
    <joint name="Rev17" type="continuous">
        <origin rpy="0 0 0" xyz="0.0 0.06 0.06" />
        <parent link="link6_1" />
        <child link="gripper_1" />
        <axis xyz="0.0 0.0 0.01" />
    </joint>
    <joint name="Rev18" type="revolute">
        <origin rpy="0 0 0" xyz="-0.020495 0.0 0.046" />
        <parent link="gripper_1" />
        <child link="jaw2_1" />
        <axis xyz="0.0 0.01 0.0" />
        <limit effort="100" lower="-1.570796" upper="0.471239" velocity="100" />
    </joint>
    <joint name="Rev19" type="revolute">
        <origin rpy="0 0 0" xyz="0.020495 0.0 0.046" />
        <parent link="gripper_1" />
        <child link="jaw1_1" />
        <axis xyz="0.0 0.01 0.0" />
        <limit effort="100" lower="-0.471239" upper="1.570796" velocity="100" />
    </joint>
    <transmission name="trans_Rev11">
        <type>transmission_interface/SimpleTransmission</type>
        <joint name="Rev11">
            <hardwareInterface>hardware_interface/PositionJointInterface</hardwareInterface>
        </joint>
        <actuator name="Rev11_motor">
            <hardwareInterface>hardware_interface/PositionJointInterface</hardwareInterface>
            <mechanicalReduction>1</mechanicalReduction>
        </actuator>
    </transmission>
    <transmission name="trans_Rev12">
        <type>transmission_interface/SimpleTransmission</type>
        <joint name="Rev12">
            <hardwareInterface>hardware_interface/PositionJointInterface</hardwareInterface>
        </joint>
        <actuator name="Rev12_motor">
            <hardwareInterface>hardware_interface/PositionJointInterface</hardwareInterface>
            <mechanicalReduction>1</mechanicalReduction>
        </actuator>
    </transmission>
    <transmission name="trans_Rev13">
        <type>transmission_interface/SimpleTransmission</type>
        <joint name="Rev13">
            <hardwareInterface>hardware_interface/PositionJointInterface</hardwareInterface>
        </joint>
        <actuator name="Rev13_motor">
            <hardwareInterface>hardware_interface/PositionJointInterface</hardwareInterface>
            <mechanicalReduction>1</mechanicalReduction>
        </actuator>
    </transmission>
    <transmission name="trans_Rev14">
        <type>transmission_interface/SimpleTransmission</type>
        <joint name="Rev14">
            <hardwareInterface>hardware_interface/PositionJointInterface</hardwareInterface>
        </joint>
        <actuator name="Rev14_motor">
            <hardwareInterface>hardware_interface/PositionJointInterface</hardwareInterface>
            <mechanicalReduction>1</mechanicalReduction>
        </actuator>
    </transmission>
    <transmission name="trans_Rev15">
        <type>transmission_interface/SimpleTransmission</type>
        <joint name="Rev15">
            <hardwareInterface>hardware_interface/PositionJointInterface</hardwareInterface>
        </joint>
        <actuator name="Rev15_motor">
            <hardwareInterface>hardware_interface/PositionJointInterface</hardwareInterface>
            <mechanicalReduction>1</mechanicalReduction>
        </actuator>
    </transmission>
    <transmission name="trans_Rev16">
        <type>transmission_interface/SimpleTransmission</type>
        <joint name="Rev16">
            <hardwareInterface>hardware_interface/PositionJointInterface</hardwareInterface>
        </joint>
        <actuator name="Rev16_motor">
            <hardwareInterface>hardware_interface/PositionJointInterface</hardwareInterface>
            <mechanicalReduction>1</mechanicalReduction>
        </actuator>
    </transmission>
    <transmission name="trans_Rev17">
        <type>transmission_interface/SimpleTransmission</type>
        <joint name="Rev17">
            <hardwareInterface>hardware_interface/EffortJointInterface</hardwareInterface>
        </joint>
        <actuator name="Rev17_motor">
            <hardwareInterface>hardware_interface/EffortJointInterface</hardwareInterface>
            <mechanicalReduction>1</mechanicalReduction>
        </actuator>
    </transmission>
    <transmission name="trans_Rev18">
        <type>transmission_interface/SimpleTransmission</type>
        <joint name="Rev18">
            <hardwareInterface>hardware_interface/EffortJointInterface</hardwareInterface>
        </joint>
        <actuator name="Rev18_motor">
            <hardwareInterface>hardware_interface/EffortJointInterface</hardwareInterface>
            <mechanicalReduction>1</mechanicalReduction>
        </actuator>
    </transmission>
    <transmission name="trans_Rev19">
        <type>transmission_interface/SimpleTransmission</type>
        <joint name="Rev19">
            <hardwareInterface>hardware_interface/EffortJointInterface</hardwareInterface>
        </joint>
        <actuator name="Rev19_motor">
            <hardwareInterface>hardware_interface/EffortJointInterface</hardwareInterface>
            <mechanicalReduction>1</mechanicalReduction>
        </actuator>
    </transmission>
    <gazebo>
        <plugin name="gazebo_ros_control" filename="libgazebo_ros_control.so">
            <robotNamespace>/</robotNamespace>
        </plugin>
    </gazebo>
</robot>

<transmission name="Rev11_tran">
        <type>transmission_interface/SimpleTransmission</type>
        <joint name="Rev11">
            <hardwareInterface>hardware_interface/EffortJointInterface</hardwareInterface>
        </joint>
        <actuator name="Rev11_actr">
            <hardwareInterface>hardware_interface/EffortJointInterface</hardwareInterface>
            <mechanicalReduction>1</mechanicalReduction>
        </actuator>
    </transmission>
    <transmission name="Rev12_tran">
        <type>transmission_interface/SimpleTransmission</type>
        <joint name="Rev12">
            <hardwareInterface>hardware_interface/EffortJointInterface</hardwareInterface>
        </joint>
        <actuator name="Rev12_actr">
            <hardwareInterface>hardware_interface/EffortJointInterface</hardwareInterface>
            <mechanicalReduction>1</mechanicalReduction>
        </actuator>
    </transmission>
    <transmission name="Rev13_tran">
        <type>transmission_interface/SimpleTransmission</type>
        <joint name="Rev13">
            <hardwareInterface>hardware_interface/EffortJointInterface</hardwareInterface>
        </joint>
        <actuator name="Rev13_actr">
            <hardwareInterface>hardware_interface/EffortJointInterface</hardwareInterface>
            <mechanicalReduction>1</mechanicalReduction>
        </actuator>
    </transmission>
    <transmission name="Rev14_tran">
        <type>transmission_interface/SimpleTransmission</type>
        <joint name="Rev14">
            <hardwareInterface>hardware_interface/EffortJointInterface</hardwareInterface>
        </joint>
        <actuator name="Rev14_actr">
            <hardwareInterface>hardware_interface/EffortJointInterface</hardwareInterface>
            <mechanicalReduction>1</mechanicalReduction>
        </actuator>
    </transmission>
    <transmission name="Rev15_tran">
        <type>transmission_interface/SimpleTransmission</type>
        <joint name="Rev15">
            <hardwareInterface>hardware_interface/EffortJointInterface</hardwareInterface>
        </joint>
        <actuator name="Rev15_actr">
            <hardwareInterface>hardware_interface/EffortJointInterface</hardwareInterface>
            <mechanicalReduction>1</mechanicalReduction>
        </actuator>
    </transmission>
    <transmission name="Rev16_tran">
        <type>transmission_interface/SimpleTransmission</type>
        <joint name="Rev16">
            <hardwareInterface>hardware_interface/EffortJointInterface</hardwareInterface>
        </joint>
        <actuator name="Rev16_actr">
            <hardwareInterface>hardware_interface/EffortJointInterface</hardwareInterface>
            <mechanicalReduction>1</mechanicalReduction>
        </actuator>
    </transmission>
    <transmission name="Rev17_tran">
        <type>transmission_interface/SimpleTransmission</type>
        <joint name="Rev17">
            <hardwareInterface>hardware_interface/EffortJointInterface</hardwareInterface>
        </joint>
        <actuator name="Rev17_actr">
            <hardwareInterface>hardware_interface/EffortJointInterface</hardwareInterface>
            <mechanicalReduction>1</mechanicalReduction>
        </actuator>
    </transmission>
    <transmission name="Rev18_tran">
        <type>transmission_interface/SimpleTransmission</type>
        <joint name="Rev18">
            <hardwareInterface>hardware_interface/EffortJointInterface</hardwareInterface>
        </joint>
        <actuator name="Rev18_actr">
            <hardwareInterface>hardware_interface/EffortJointInterface</hardwareInterface>
            <mechanicalReduction>1</mechanicalReduction>
        </actuator>
    </transmission>
    <transmission name="Rev19_tran">
        <type>transmission_interface/SimpleTransmission</type>
        <joint name="Rev19">
            <hardwareInterface>hardware_interface/EffortJointInterface</hardwareInterface>
        </joint>
        <actuator name="Rev19_actr">
            <hardwareInterface>hardware_interface/EffortJointInterface</hardwareInterface>
            <mechanicalReduction>1</mechanicalReduction>
        </actuator>
    </transmission>
    <gazebo>
        <plugin filename="libgazebo_ros_control.so" name="control" />
    </gazebo>
    <gazebo reference="base_link">
        <material>Gazebo/Silver</material>
        <mu1>0.2</mu1>
        <mu2>0.2</mu2>
        <selfCollide>true</selfCollide>
        <gravity>true</gravity>
    </gazebo>
    <gazebo reference="link1_1">
        <material>Gazebo/Silver</material>
        <mu1>0.2</mu1>
        <mu2>0.2</mu2>
        <selfCollide>true</selfCollide>
    </gazebo>
    <gazebo reference="link2_1">
        <material>Gazebo/Silver</material>
        <mu1>0.2</mu1>
        <mu2>0.2</mu2>
        <selfCollide>true</selfCollide>
    </gazebo>
    <gazebo reference="link3_1">
        <material>Gazebo/Silver</material>
        <mu1>0.2</mu1>
        <mu2>0.2</mu2>
        <selfCollide>true</selfCollide>
    </gazebo>
    <gazebo reference="link4_1">
        <material>Gazebo/Silver</material>
        <mu1>0.2</mu1>
        <mu2>0.2</mu2>
        <selfCollide>true</selfCollide>
    </gazebo>
    <gazebo reference="link5_1">
        <material>Gazebo/Silver</material>
        <mu1>0.2</mu1>
        <mu2>0.2</mu2>
        <selfCollide>true</selfCollide>
    </gazebo>
    <gazebo reference="link6_1">
        <material>Gazebo/Silver</material>
        <mu1>0.2</mu1>
        <mu2>0.2</mu2>
        <selfCollide>true</selfCollide>
    </gazebo>
    <gazebo reference="gripper_1">
        <material>Gazebo/Silver</material>
        <mu1>0.2</mu1>
        <mu2>0.2</mu2>
        <selfCollide>true</selfCollide>
    </gazebo>
    <gazebo reference="jaw2_1">
        <material>Gazebo/Silver</material>
        <mu1>0.2</mu1>
        <mu2>0.2</mu2>
        <selfCollide>true</selfCollide>
    </gazebo>
    <gazebo reference="jaw1_1">
        <material>Gazebo/Silver</material>
        <mu1>0.2</mu1>
        <mu2>0.2</mu2>
        <selfCollide>true</selfCollide>
    </gazebo>
    <link name="base_link">
        <visual>
            <origin rpy="0 0 0" xyz="0 0 0" />
            <geometry>
                <mesh filename="package://robotic_arm_description/meshes/base_link.stl" scale="0.001 0.001 0.001" />
            </geometry>
            <material name="silver" />
        </visual>
        <collision>
            <origin rpy="0 0 0" xyz="0 0 0" />
            <geometry>
                <mesh filename="package://robotic_arm_description/meshes/base_link.stl" scale="0.001 0.001 0.001" />
            </geometry>
        </collision>
        <inertial>
            <mass value="0.1" />
            <inertia ixx="0.03" iyy="0.03" izz="0.03" ixy="0.0" ixz="0.0" iyz="0.0" />
        </inertial>
    </link>
    <link name="link1_1">
        <inertial>
            <origin rpy="0 0 0" xyz="-0.014103177682961474 2.911659828472621e-08 0.09630243018941843" />
            <mass value="9.886638889856904" />
            <inertia ixx="0.028938" ixy="0.0" ixz="0.00225" iyy="0.029652" iyz="0.0" izz="0.010294" />
        </inertial>
        <visual>
            <origin rpy="0 0 0" xyz="-0.0 -0.0 -0.082" />
            <geometry>
                <mesh filename="package://robotic_arm_description/meshes/link1_1.stl" scale="0.001 0.001 0.001" />
            </geometry>
            <material name="silver" />
        </visual>
        <collision>
            <origin rpy="0 0 0" xyz="-0.0 -0.0 -0.082" />
            <geometry>
                <mesh filename="package://robotic_arm_description/meshes/link1_1.stl" scale="0.001 0.001 0.001" />
            </geometry>
        </collision>
    </link>
    <link name="link2_1">
        <inertial>
            <origin rpy="0 0 0" xyz="0.03900552900187564 -4.720497574409756e-08 0.03774797355252993" />
            <mass value="8.491131635058604" />
            <inertia ixx="0.028031" ixy="0.0" ixz="0.002228" iyy="0.028711" iyz="0.0" izz="0.009465" />
        </inertial>
        <visual>
            <origin rpy="0 0 0" xyz="-0.025 -0.0 -0.214" />
            <geometry>
                <mesh filename="package://robotic_arm_description/meshes/link2_1.stl" scale="0.001 0.001 0.001" />
            </geometry>
            <material name="silver" />
        </visual>
        <collision>
            <origin rpy="0 0 0" xyz="-0.025 -0.0 -0.214" />
            <geometry>
                <mesh filename="package://robotic_arm_description/meshes/link2_1.stl" scale="0.001 0.001 0.001" />
            </geometry>
        </collision>
    </link>
    <link name="link3_1">
        <inertial>
            <origin rpy="0 0 0" xyz="0.012475562747510771 1.9427211413704553e-08 0.09282105705277077" />
            <mass value="8.19717066814797" />
            <inertia ixx="0.027193" ixy="0.0" ixz="-0.001721" iyy="0.027471" iyz="0.0" izz="0.008682" />
        </inertial>
        <visual>
            <origin rpy="0 0 0" xyz="-0.05 -0.0 -0.346" />
            <geometry>
                <mesh filename="package://robotic_arm_description/meshes/link3_1.stl" scale="0.001 0.001 0.001" />
            </geometry>
            <material name="silver" />
        </visual>
        <collision>
            <origin rpy="0 0 0" xyz="-0.05 -0.0 -0.346" />
            <geometry>
                <mesh filename="package://robotic_arm_description/meshes/link3_1.stl" scale="0.001 0.001 0.001" />
            </geometry>
        </collision>
    </link>
    <link name="link4_1">
        <inertial>
            <origin rpy="0 0 0" xyz="-0.0374755647664739 1.4871117923491877e-08 0.03917892822918834" />
            <mass value="8.197173492795319" />
            <inertia ixx="0.027193" ixy="-0.0" ixz="-0.001721" iyy="0.027471" iyz="-0.0" izz="0.008682" />
        </inertial>
        <visual>
            <origin rpy="0 0 0" xyz="-0.025 -0.0 -0.478" />
            <geometry>
                <mesh filename="package://robotic_arm_description/meshes/link4_1.stl" scale="0.001 0.001 0.001" />
            </geometry>
            <material name="silver" />
        </visual>
        <collision>
            <origin rpy="0 0 0" xyz="-0.025 -0.0 -0.478" />
            <geometry>
                <mesh filename="package://robotic_arm_description/meshes/link4_1.stl" scale="0.001 0.001 0.001" />
            </geometry>
        </collision>
    </link>
    <link name="link5_1">
        <inertial>
            <origin rpy="0 0 0" xyz="5.829486113497266e-07 -0.013599717850522941 0.035950542831699184" />
            <mass value="2.7272453464013666" />
            <inertia ixx="0.005718" ixy="0.0" ixz="-0.0" iyy="0.005217" iyz="0.001527" izz="0.003392" />
        </inertial>
        <visual>
            <origin rpy="0 0 0" xyz="0.0 -0.0 -0.61" />
            <geometry>
                <mesh filename="package://robotic_arm_description/meshes/link5_1.stl" scale="0.001 0.001 0.001" />
            </geometry>
            <material name="silver" />
        </visual>
        <collision>
            <origin rpy="0 0 0" xyz="0.0 -0.0 -0.61" />
            <geometry>
                <mesh filename="package://robotic_arm_description/meshes/link5_1.stl" scale="0.001 0.001 0.001" />
            </geometry>
        </collision>
    </link>
    <link name="link6_1">
        <inertial>
            <origin rpy="0 0 0" xyz="1.2404412177094015e-07 0.043907868057215506 0.00576385697550974" />
            <mass value="3.0329082890678123" />
            <inertia ixx="0.00335" ixy="0.0" ixz="-0.0" iyy="0.002555" iyz="-0.000289" izz="0.002524" />
        </inertial>
        <visual>
            <origin rpy="0 0 0" xyz="0.0 0.035 -0.737" />
            <geometry>
                <mesh filename="package://robotic_arm_description/meshes/link6_1.stl" scale="0.001 0.001 0.001" />
            </geometry>
            <material name="silver" />
        </visual>
        <collision>
            <origin rpy="0 0 0" xyz="0.0 0.035 -0.737" />
            <geometry>
                <mesh filename="package://robotic_arm_description/meshes/link6_1.stl" scale="0.001 0.001 0.001" />
            </geometry>
        </collision>
    </link>
    <link name="gripper_1">
        <inertial>
            <origin rpy="0 0 0" xyz="6.519052686577514e-09 -0.00043894585194131225 0.008806436122391847" />
            <mass value="0.14002124283631304" />
            <inertia ixx="2.9e-05" ixy="0.0" ixz="0.0" iyy="4.7e-05" iyz="1e-06" izz="4.2e-05" />
        </inertial>
        <visual>
            <origin rpy="0 0 0" xyz="-0.0 -0.025 -0.797" />
            <geometry>
                <mesh filename="package://robotic_arm_description/meshes/gripper_1.stl" scale="0.001 0.001 0.001" />
            </geometry>
            <material name="silver" />
        </visual>
        <collision>
            <origin rpy="0 0 0" xyz="-0.0 -0.025 -0.797" />
            <geometry>
                <mesh filename="package://robotic_arm_description/meshes/gripper_1.stl" scale="0.001 0.001 0.001" />
            </geometry>
        </collision>
    </link>
    <link name="jaw2_1">
        <inertial>
            <origin rpy="0 0 0" xyz="0.000131421896564822 0.0024996154528694157 0.015252945027369291" />
            <mass value="0.011516853958458544" />
            <inertia ixx="1e-06" ixy="0.0" ixz="-0.0" iyy="1e-06" iyz="-0.0" izz="0.0" />
        </inertial>
        <visual>
            <origin rpy="0 0 0" xyz="0.020495 -0.025 -0.843" />
            <geometry>
                <mesh filename="package://robotic_arm_description/meshes/jaw2_1.stl" scale="0.001 0.001 0.001" />
            </geometry>
            <material name="silver" />
        </visual>
        <collision>
            <origin rpy="0 0 0" xyz="0.020495 -0.025 -0.843" />
            <geometry>
                <mesh filename="package://robotic_arm_description/meshes/jaw2_1.stl" scale="0.001 0.001 0.001" />
            </geometry>
        </collision>
    </link>
    <link name="jaw1_1">
        <inertial>
            <origin rpy="0 0 0" xyz="-0.0001314218965648116 0.0024996154528694157 0.015252945027369291" />
            <mass value="0.011516853958458544" />
            <inertia ixx="1e-06" ixy="0.0" ixz="0.0" iyy="1e-06" iyz="-0.0" izz="0.0" />
        </inertial>
        <visual>
            <origin rpy="0 0 0" xyz="-0.020495 -0.025 -0.843" />
            <geometry>
                <mesh filename="package://robotic_arm_description/meshes/jaw1_1.stl" scale="0.001 0.001 0.001" />
            </geometry>
            <material name="silver" />
        </visual>
        <collision>
            <origin rpy="0 0 0" xyz="-0.020495 -0.025 -0.843" />
            <geometry>
                <mesh filename="package://robotic_arm_description/meshes/jaw1_1.stl" scale="0.001 0.001 0.001" />
            </geometry>
        </collision>
    </link>
    <joint name="Rev11" type="continuous">
        <origin rpy="0 0 0" xyz="0.0 0.0 0.082" />
        <parent link="base_link" />
        <child link="link1_1" />
        <axis xyz="0.0 0.0 0.01" />
    </joint>
    <joint name="Rev12" type="revolute">
        <origin rpy="0 0 0" xyz="0.025 0.0 0.132" />
        <parent link="link1_1" />
        <child link="link2_1" />
        <axis xyz="0.01 0.0 0.0" />
        <limit effort="100" lower="-1.570796" upper="1.570796" velocity="100" />
    </joint>
    <joint name="Rev13" type="continuous">
        <origin rpy="0 0 0" xyz="0.025 0.0 0.132" />
        <parent link="link2_1" />
        <child link="link3_1" />
        <axis xyz="0.0 0.0 0.01" />
    </joint>
    <joint name="Rev14" type="revolute">
        <origin rpy="0 0 0" xyz="-0.025 0.0 0.132" />
        <parent link="link3_1" />
        <child link="link4_1" />
        <axis xyz="-0.01 0.0 0.0" />
        <limit effort="100" lower="-1.570796" upper="1.570796" velocity="100" />
    </joint>
    <joint name="Rev15" type="continuous">
        <origin rpy="0 0 0" xyz="-0.025 0.0 0.132" />
        <parent link="link4_1" />
        <child link="link5_1" />
        <axis xyz="0.0 -0.0 0.01" />
    </joint>
    <joint name="Rev16" type="revolute">
        <origin rpy="0 0 0" xyz="0.0 -0.035 0.127" />
        <parent link="link5_1" />
        <child link="link6_1" />
        <axis xyz="0.0 0.01 0.0" />
        <limit effort="100" lower="-1.570796" upper="1.570796" velocity="100" />
    </joint>
    <joint name="Rev17" type="continuous">
        <origin rpy="0 0 0" xyz="0.0 0.06 0.06" />
        <parent link="link6_1" />
        <child link="gripper_1" />
        <axis xyz="0.0 0.0 0.01" />
    </joint>
    <joint name="Rev18" type="revolute">
        <origin rpy="0 0 0" xyz="-0.020495 0.0 0.046" />
        <parent link="gripper_1" />
        <child link="jaw2_1" />
        <axis xyz="0.0 0.01 0.0" />
        <limit effort="100" lower="-1.570796" upper="0.471239" velocity="100" />
    </joint>
    <joint name="Rev19" type="revolute">
        <origin rpy="0 0 0" xyz="0.020495 0.0 0.046" />
        <parent link="gripper_1" />
        <child link="jaw1_1" />
        <axis xyz="0.0 0.01 0.0" />
        <limit effort="100" lower="-0.471239" upper="1.570796" velocity="100" />
    </joint>
    <transmission name="trans_Rev11">
        <type>transmission_interface/SimpleTransmission</type>
        <joint name="Rev11">
            <hardwareInterface>hardware_interface/PositionJointInterface</hardwareInterface>
        </joint>
        <actuator name="Rev11_motor">
            <hardwareInterface>hardware_interface/PositionJointInterface</hardwareInterface>
            <mechanicalReduction>1</mechanicalReduction>
        </actuator>
    </transmission>
    <transmission name="trans_Rev12">
        <type>transmission_interface/SimpleTransmission</type>
        <joint name="Rev12">
            <hardwareInterface>hardware_interface/PositionJointInterface</hardwareInterface>
        </joint>
        <actuator name="Rev12_motor">
            <hardwareInterface>hardware_interface/PositionJointInterface</hardwareInterface>
            <mechanicalReduction>1</mechanicalReduction>
        </actuator>
    </transmission>
    <transmission name="trans_Rev13">
        <type>transmission_interface/SimpleTransmission</type>
        <joint name="Rev13">
            <hardwareInterface>hardware_interface/PositionJointInterface</hardwareInterface>
        </joint>
        <actuator name="Rev13_motor">
            <hardwareInterface>hardware_interface/PositionJointInterface</hardwareInterface>
            <mechanicalReduction>1</mechanicalReduction>
        </actuator>
    </transmission>
    <transmission name="trans_Rev14">
        <type>transmission_interface/SimpleTransmission</type>
        <joint name="Rev14">
            <hardwareInterface>hardware_interface/PositionJointInterface</hardwareInterface>
        </joint>
        <actuator name="Rev14_motor">
            <hardwareInterface>hardware_interface/PositionJointInterface</hardwareInterface>
            <mechanicalReduction>1</mechanicalReduction>
        </actuator>
    </transmission>
    <transmission name="trans_Rev15">
        <type>transmission_interface/SimpleTransmission</type>
        <joint name="Rev15">
            <hardwareInterface>hardware_interface/PositionJointInterface</hardwareInterface>
        </joint>
        <actuator name="Rev15_motor">
            <hardwareInterface>hardware_interface/PositionJointInterface</hardwareInterface>
            <mechanicalReduction>1</mechanicalReduction>
        </actuator>
    </transmission>
    <transmission name="trans_Rev16">
        <type>transmission_interface/SimpleTransmission</type>
        <joint name="Rev16">
            <hardwareInterface>hardware_interface/PositionJointInterface</hardwareInterface>
        </joint>
        <actuator name="Rev16_motor">
            <hardwareInterface>hardware_interface/PositionJointInterface</hardwareInterface>
            <mechanicalReduction>1</mechanicalReduction>
        </actuator>
    </transmission>
    <transmission name="trans_Rev17">
        <type>transmission_interface/SimpleTransmission</type>
        <joint name="Rev17">
            <hardwareInterface>hardware_interface/EffortJointInterface</hardwareInterface>
        </joint>
        <actuator name="Rev17_motor">
            <hardwareInterface>hardware_interface/EffortJointInterface</hardwareInterface>
            <mechanicalReduction>1</mechanicalReduction>
        </actuator>
    </transmission>
    <transmission name="trans_Rev18">
        <type>transmission_interface/SimpleTransmission</type>
        <joint name="Rev18">
            <hardwareInterface>hardware_interface/EffortJointInterface</hardwareInterface>
        </joint>
        <actuator name="Rev18_motor">
            <hardwareInterface>hardware_interface/EffortJointInterface</hardwareInterface>
            <mechanicalReduction>1</mechanicalReduction>
        </actuator>
    </transmission>
    <transmission name="trans_Rev19">
        <type>transmission_interface/SimpleTransmission</type>
        <joint name="Rev19">
            <hardwareInterface>hardware_interface/EffortJointInterface</hardwareInterface>
        </joint>
        <actuator name="Rev19_motor">
            <hardwareInterface>hardware_interface/EffortJointInterface</hardwareInterface>
            <mechanicalReduction>1</mechanicalReduction>
        </actuator>
    </transmission>
    <gazebo>
        <plugin name="gazebo_ros_control" filename="libgazebo_ros_control.so">
            <robotNamespace>/</robotNamespace>
        </plugin>
    </gazebo>
</robot>